Workbook

Sheet Detail Data
B1: DROPPING REPORT
B2: PERIOD | C2: 2025-12 | X2: All sales | AD2: '=PO lines yang masih open - GIT | AE2: =Cons stock available + On hand FGB cab > 6 bln + GIT + PO Pending
B3: BRANCH | C3: NASIONAL
B4: UPTODATE | C4: 15/01/2026 | J4: Hanya SALES Reguler (diluar Promosi, Tender, Ecatalog) | AY4: Akan dipakai di Pesta Online
A5: BRANCH | B5: PM NAME | C5: SUPPLIER | D5: SALES GROUP | E5: PART NO | F5: DESCRIPTION | G5: CATEGORY | H5: DROPPING STATUS | I5: HNA UM | J5: 2025-01 | K5: 2025-02 | L5: 2025-03 | M5: 2025-04 | N5: 2025-05 | O5: 2025-06 | P5: 2025-07 | Q5: 2025-08 | R5: 2025-09 | S5: 2025-10 | T5: 2025-11 | U5: 2025-12 | V5: AMS3 QTY | W5: AMS 2+1 | X5: QTY SALES YESTERDAY | Y5: INITIAL STOCK | Z5: CONS STOCK AVAILABLE | AA5: ON HAND FGB CAB > 6 bln | AB5: ON HAND FGB CAB <= 6 bln | AC5: GIT | AD5: PO PENDING | AE5: GROSS STOCK | AF5: DOI CAB (GROSS) to AMS3 | AG5: DOI OH | AH5: STOCK KPST AVAILABLE > 6 bln | AI5: STOCK KPST AVAILABLE <= 6 bln | AJ5: PO OUTSTANDING PRINCIPAL | AK5: BEST ESTIMATE DEC | AL5: FORECAST FINAL JAN | AM5: INDEX REGULAR | AN5: BUFFER | AO5: MASTER BOX | AP5: KELIPATAN KIRIM | AQ5: SOURCE (KPST/DIRECT) | AR5: FREKUENSI KIRIM | AS5: LT | AT5: MODA | AU5: RENCANA DROPPING NOV | AV5: RENCANA DROPPING NOV (master box) | AW5: DOI AFTER DROPPING (master box) | AX5: DOI AFTER DROPPING (Kelipatan kirim) | AY5: RENCANA DROPPING | AZ5: DROPPING SESUAI STOCK KPST | BA5: PRIORITAS DROPPING | BB5: KUBIKASI | BC5: TOTAL KUBIKASI | BD5: KUMULATIF KUBIKASI | BE5: BERAT | BF5: TOTAL BERAT | BG5: KUMULATIF BERAT | BH5: REFERENCE PO | BI5: SPECIAL HANDLING | BJ5: ZONASI | BK5: UOM VOLUME | BL5: UOM WEIGHT
A6: BDG1 | B6: SUHADI | C6: ULTRA SAKTI | D6: 4P719 | E6: P7100002 | F6: INDAL - CTN @10 TAB AMPLOP | G6: FAST MOVING | H6: DROPPING | I6: 16500 | J6: 1610 | K6: 2021 | L6: 2133 | M6: 2424 | N6: 3385 | O6: 2518 | P6: 2340 | Q6: 3228 | R6: 841 | S6: 3782 | T6: 3746 | U6: 2116 | V6: 3214.6667 | W6: =AVERAGE(T6,U6,AL6) -> 3020 | X6: 579 | Y6: 0 | Z6: 0 | AA6: 2595 | AB6: 0 | AC6: 1200 | AD6: 0 | AE6: =Z6+AA6+AC6+AD6 -> 3795 | AF6: =IFERROR(IF(V6<0,9999,AE6/V6),9999) -> 1.1805268 | AG6: =IFERROR(IF(W6<0,9999,(Z6+AA6+AC6)/W6),9999) -> 1.2566225 | AH6: 10200 | AI6: 0 | AJ6: 10200 | AK6: 2906 | AL6: 3198 | AM6: 0.7 | AN6: =IF(AM6*W6<0,0,AM6*W6) -> 2114 | AO6: 120 | AP6: 120 | AQ6: KPST | AR6: 8 | AS6: 0.066666667 | AT6: NON UDARA | AU6: =IF(OR(H6="PINDAH DISTRIBUTOR",H6="PESTA NO BUFFER",H6="PESTA"),0,IF(AL6+AN6<AE6,0,IF((0.75*((AL6+AN6)-AE6))<0,0,0.75*((AL6+AN6)-AE6)))) -> 1137.75 | AV6: =IFERROR(ROUNDUP(AU6/AO6,0)*AO6,9999) -> 1200 | AW6: =IFERROR(IF(W6<0,9999,((ROUNDUP(AU6/AO6,0)*AO6)+AE6)/W6),9999) -> 1.6539735 | AX6: =IFERROR(IF(W6<0,9999,((ROUNDUP(AU6/AP6,0)*AP6)+AE6-AL6)/W6),9999) -> 0.59503311 | AY6: =IF(H6="DROPPING",IF(AND(AW6>3,AX6>3),0,IF(AND(AW6<=3,AX6<=3),ROUNDUP(AU6/AO6,0)*AO6,ROUNDUP(AU6/AP6,0)*AP6)),0) -> 1200 | AZ6: =IF(AH6<=0,0,IF(H6="DROPPING",IF(AND(AW6>3,AX6>3),0,IF(AND(AW6<=3,AX6<=3),ROUNDUP(AU6/AO6,0)*AO6,ROUNDUP(AU6/AP6,0)*AP6)),0)) -> 1200 | BA6: =IF(AND(AW6>3,AX6>3),"Kelipatan Kirim/Master box > 3x FC+index",IF(AF6<=AS6,"1",IF(AND(AF6>AS6,AF6<=AM6),"2","3"))) -> 3 | BB6: 0.00076752 | BC6: =BB6*AZ6 -> 0.921024 | BD6: =#REF!+BC6 -> #REF! | BE6: 0.121 | BF6: =BE6*AY6 -> 145.2 | BG6: =#REF!+BF6 -> #REF! | BH6: =IF(AT6="UDARA","U","N")&LEFT($C$4,2)&MID($C$4,4,2)&LEFT(A6,3)&MID(E6,2,2)&VLOOKUP(E6,Acuan_Reference!C:L,10,0) -> N1501BDG71ED | BI6: SUHU NORMAL | BJ6: FAR2 | BK6: CM3 | BL6: G
A7: BGR1 | B7: SUHADI | C7: ULTRA SAKTI | D7: 4P719 | E7: P7100002 | F7: INDAL - CTN @10 TAB AMPLOP | G7: FAST MOVING | H7: DROPPING | I7: 16500 | J7: 314 | K7: 271 | L7: 252 | M7: 435 | N7: 292 | O7: 305 | P7: 337 | Q7: 241 | R7: 301 | S7: 517 | T7: 218 | U7: 309 | V7: 348 | W7: =AVERAGE(T7,U7,AL7) -> 307.66667 | X7: 56 | Y7: 0 | Z7: 0 | AA7: 349 | AB7: 0 | AC7: 120 | AD7: 0 | AE7: =Z7+AA7+AC7+AD7 -> 469 | AF7: =IFERROR(IF(V7<0,9999,AE7/V7),9999) -> 1.3477011 | AG7: =IFERROR(IF(W7<0,9999,(Z7+AA7+AC7)/W7),9999) -> 1.524377 | AH7: 10200 | AI7: 0 | AJ7: 10200 | AK7: 393 | AL7: 396 | AM7: 0.6 | AN7: =IF(AM7*W7<0,0,AM7*W7) -> 184.6 | AO7: 120 | AP7: 120 | AQ7: KPST | AR7: 8 | AS7: 0.033333333 | AT7: NON UDARA | AU7: =IF(OR(H7="PINDAH DISTRIBUTOR",H7="PESTA NO BUFFER",H7="PESTA"),0,IF(AL7+AN7<AE7,0,IF((0.75*((AL7+AN7)-AE7))<0,0,0.75*((AL7+AN7)-AE7)))) -> 83.7 | AV7: =IFERROR(ROUNDUP(AU7/AO7,0)*AO7,9999) -> 120 | AW7: =IFERROR(IF(W7<0,9999,((ROUNDUP(AU7/AO7,0)*AO7)+AE7)/W7),9999) -> 1.9144095 | AX7: =IFERROR(IF(W7<0,9999,((ROUNDUP(AU7/AP7,0)*AP7)+AE7-AL7)/W7),9999) -> 0.62730228 | AY7: =IF(H7="DROPPING",IF(AND(AW7>3,AX7>3),0,IF(AND(AW7<=3,AX7<=3),ROUNDUP(AU7/AO7,0)*AO7,ROUNDUP(AU7/AP7,0)*AP7)),0) -> 120 | AZ7: =IF(AH7<=0,0,IF(H7="DROPPING",IF(AND(AW7>3,AX7>3),0,IF(AND(AW7<=3,AX7<=3),ROUNDUP(AU7/AO7,0)*AO7,ROUNDUP(AU7/AP7,0)*AP7)),0)) -> 120 | BA7: =IF(AND(AW7>3,AX7>3),"Kelipatan Kirim/Master box > 3x FC+index",IF(AF7<=AS7,"1",IF(AND(AF7>AS7,AF7<=AM7),"2","3"))) -> 3 | BB7: 0.00076752 | BC7: =BB7*AZ7 -> 0.0921024 | BD7: =BD6+BC7 -> #REF! | BE7: 0.121 | BF7: =BE7*AY7 -> 14.52 | BG7: =BG6+BF7 -> #REF! | BH7: =IF(AT7="UDARA","U","N")&LEFT($C$4,2)&MID($C$4,4,2)&LEFT(A7,3)&MID(E7,2,2)&VLOOKUP(E7,Acuan_Reference!C:L,10,0) -> N1501BGR71ED | BI7: SUHU NORMAL | BJ7: FAR2 | BK7: CM3 | BL7: G
A8: BJM1 | B8: SUHADI | C8: ULTRA SAKTI | D8: 4P719 | E8: P7100002 | F8: INDAL - CTN @10 TAB AMPLOP | G8: FAST MOVING | H8: DROPPING | I8: 16500 | J8: 246 | K8: 345 | L8: 348 | M8: 312 | N8: 441 | O8: 98 | P8: 113 | Q8: 126 | R8: 333 | S8: 310 | T8: 206 | U8: 290 | V8: 268.66667 | W8: =AVERAGE(T8,U8,AL8) -> 273.66667 | X8: 156 | Y8: 0 | Z8: 0 | AA8: 440 | AB8: 0 | AC8: 240 | AD8: 0 | AE8: =Z8+AA8+AC8+AD8 -> 680 | AF8: =IFERROR(IF(V8<0,9999,AE8/V8),9999) -> 2.5310174 | AG8: =IFERROR(IF(W8<0,9999,(Z8+AA8+AC8)/W8),9999) -> 2.4847747 | AH8: 10200 | AI8: 0 | AJ8: 10200 | AK8: 285 | AL8: 325 | AM8: 1.3 | AN8: =IF(AM8*W8<0,0,AM8*W8) -> 355.76667 | AO8: 120 | AP8: 120 | AQ8: KPST | AR8: 4 | AS8: 0.53333333 | AT8: NON UDARA | AU8: =IF(OR(H8="PINDAH DISTRIBUTOR",H8="PESTA NO BUFFER",H8="PESTA"),0,IF(AL8+AN8<AE8,0,IF((0.75*((AL8+AN8)-AE8))<0,0,0.75*((AL8+AN8)-AE8)))) -> 0.575 | AV8: =IFERROR(ROUNDUP(AU8/AO8,0)*AO8,9999) -> 120 | AW8: =IFERROR(IF(W8<0,9999,((ROUNDUP(AU8/AO8,0)*AO8)+AE8)/W8),9999) -> 2.9232643 | AX8: =IFERROR(IF(W8<0,9999,((ROUNDUP(AU8/AP8,0)*AP8)+AE8-AL8)/W8),9999) -> 1.7356882 | AY8: =IF(H8="DROPPING",IF(AND(AW8>3,AX8>3),0,IF(AND(AW8<=3,AX8<=3),ROUNDUP(AU8/AO8,0)*AO8,ROUNDUP(AU8/AP8,0)*AP8)),0) -> 120 | AZ8: =IF(AH8<=0,0,IF(H8="DROPPING",IF(AND(AW8>3,AX8>3),0,IF(AND(AW8<=3,AX8<=3),ROUNDUP(AU8/AO8,0)*AO8,ROUNDUP(AU8/AP8,0)*AP8)),0)) -> 120 | BA8: =IF(AND(AW8>3,AX8>3),"Kelipatan Kirim/Master box > 3x FC+index",IF(AF8<=AS8,"1",IF(AND(AF8>AS8,AF8<=AM8),"2","3"))) -> 3 | BB8: 0.00076752 | BC8: =BB8*AZ8 -> 0.0921024 | BD8: =BD7+BC8 -> #REF! | BE8: 0.121 | BF8: =BE8*AY8 -> 14.52 | BG8: =BG7+BF8 -> #REF! | BH8: =IF(AT8="UDARA","U","N")&LEFT($C$4,2)&MID($C$4,4,2)&LEFT(A8,3)&MID(E8,2,2)&VLOOKUP(E8,Acuan_Reference!C:L,10,0) -> N1501BJM71ED | BI8: SUHU NORMAL | BJ8: FAR2 | BK8: CM3 | BL8: G
A9: BKS1 | B9: SUHADI | C9: ULTRA SAKTI | D9: 4P719 | E9: P7100002 | F9: INDAL - CTN @10 TAB AMPLOP | G9: FAST MOVING | H9: DROPPING | I9: 16500 | J9: 1277 | K9: 1317 | L9: 1256 | M9: 1784 | N9: 1480 | O9: 1138 | P9: 1455 | Q9: 1827 | R9: 1015 | S9: 1737 | T9: 1037 | U9: 1430 | V9: 1401.3333 | W9: =AVERAGE(T9,U9,AL9) -> 1305 | X9: 654 | Y9: 0 | Z9: 0 | AA9: 1198 | AB9: 0 | AC9: 0 | AD9: 0 | AE9: =Z9+AA9+AC9+AD9 -> 1198 | AF9: =IFERROR(IF(V9<0,9999,AE9/V9),9999) -> 0.8549001 | AG9: =IFERROR(IF(W9<0,9999,(Z9+AA9+AC9)/W9),9999) -> 0.91800766 | AH9: 10200 | AI9: 0 | AJ9: 10200 | AK9: 1696 | AL9: 1448 | AM9: 0.6 | AN9: =IF(AM9*W9<0,0,AM9*W9) -> 783 | AO9: 120 | AP9: 120 | AQ9: KPST | AR9: 12 | AS9: 0.033333333 | AT9: NON UDARA | AU9: =IF(OR(H9="PINDAH DISTRIBUTOR",H9="PESTA NO BUFFER",H9="PESTA"),0,IF(AL9+AN9<AE9,0,IF((0.75*((AL9+AN9)-AE9))<0,0,0.75*((AL9+AN9)-AE9)))) -> 774.75 | AV9: =IFERROR(ROUNDUP(AU9/AO9,0)*AO9,9999) -> 840 | AW9: =IFERROR(IF(W9<0,9999,((ROUNDUP(AU9/AO9,0)*AO9)+AE9)/W9),9999) -> 1.5616858 | AX9: =IFERROR(IF(W9<0,9999,((ROUNDUP(AU9/AP9,0)*AP9)+AE9-AL9)/W9),9999) -> 0.45210728 | AY9: =IF(H9="DROPPING",IF(AND(AW9>3,AX9>3),0,IF(AND(AW9<=3,AX9<=3),ROUNDUP(AU9/AO9,0)*AO9,ROUNDUP(AU9/AP9,0)*AP9)),0) -> 840 | AZ9: =IF(AH9<=0,0,IF(H9="DROPPING",IF(AND(AW9>3,AX9>3),0,IF(AND(AW9<=3,AX9<=3),ROUNDUP(AU9/AO9,0)*AO9,ROUNDUP(AU9/AP9,0)*AP9)),0)) -> 840 | BA9: =IF(AND(AW9>3,AX9>3),"Kelipatan Kirim/Master box > 3x FC+index",IF(AF9<=AS9,"1",IF(AND(AF9>AS9,AF9<=AM9),"2","3"))) -> 3 | BB9: 0.00076752 | BC9: =BB9*AZ9 -> 0.6447168 | BD9: =BD8+BC9 -> #REF! | BE9: 0.121 | BF9: =BE9*AY9 -> 101.64 | BG9: =BG8+BF9 -> #REF! | BH9: =IF(AT9="UDARA","U","N")&LEFT($C$4,2)&MID($C$4,4,2)&LEFT(A9,3)&MID(E9,2,2)&VLOOKUP(E9,Acuan_Reference!C:L,10,0) -> N1501BKS71ED | BI9: SUHU NORMAL | BJ9: FAR2 | BK9: CM3 | BL9: G
A10: BLP1 | B10: SUHADI | C10: ULTRA SAKTI | D10: 4P719 | E10: P7100002 | F10: INDAL - CTN @10 TAB AMPLOP | G10: FAST MOVING | H10: DROPPING | I10: 16500 | J10: 261 | K10: 458 | L10: 285 | M10: 279 | N10: 387 | O10: 175 | P10: 176 | Q10: 194 | R10: 218 | S10: 352 | T10: 312 | U10: 297 | V10: 320.33333 | W10: =AVERAGE(T10,U10,AL10) -> 315.66667 | X10: 162 | Y10: 0 | Z10: 0 | AA10: 277 | AB10: 0 | AC10: 240 | AD10: 0 | AE10: =Z10+AA10+AC10+AD10 -> 517 | AF10: =IFERROR(IF(V10<0,9999,AE10/V10),9999) -> 1.6139438 | AG10: =IFERROR(IF(W10<0,9999,(Z10+AA10+AC10)/W10),9999) -> 1.6378036 | AH10: 10200 | AI10: 0 | AJ10: 10200 | AK10: 284 | AL10: 338 | AM10: 0.9 | AN10: =IF(AM10*W10<0,0,AM10*W10) -> 284.1 | AO10: 120 | AP10: 120 | AQ10: KPST | AR10: 4 | AS10: 0.13333333 | AT10: NON UDARA | AU10: =IF(OR(H10="PINDAH DISTRIBUTOR",H10="PESTA NO BUFFER",H10="PESTA"),0,IF(AL10+AN10<AE10,0,IF((0.75*((AL10+AN10)-AE10))<0,0,0.75*((AL10+AN10)-AE10)))) -> 78.825 | AV10: =IFERROR(ROUNDUP(AU10/AO10,0)*AO10,9999) -> 120 | AW10: =IFERROR(IF(W10<0,9999,((ROUNDUP(AU10/AO10,0)*AO10)+AE10)/W10),9999) -> 2.0179514 | AX10: =IFERROR(IF(W10<0,9999,((ROUNDUP(AU10/AP10,0)*AP10)+AE10-AL10)/W10),9999) -> 0.94720169 | AY10: =IF(H10="DROPPING",IF(AND(AW10>3,AX10>3),0,IF(AND(AW10<=3,AX10<=3),ROUNDUP(AU10/AO10,0)*AO10,ROUNDUP(AU10/AP10,0)*AP10)),0) -> 120 | AZ10: =IF(AH10<=0,0,IF(H10="DROPPING",IF(AND(AW10>3,AX10>3),0,IF(AND(AW10<=3,AX10<=3),ROUNDUP(AU10/AO10,0)*AO10,ROUNDUP(AU10/AP10,0)*AP10)),0)) -> 120 | BA10: =IF(AND(AW10>3,AX10>3),"Kelipatan Kirim/Master box > 3x FC+index",IF(AF10<=AS10,"1",IF(AND(AF10>AS10,AF10<=AM10),"2","3"))) -> 3 | BB10: 0.00076752 | BC10: =BB10*AZ10 -> 0.0921024 | BD10: =BD9+BC10 -> #REF! | BE10: 0.121 | BF10: =BE10*AY10 -> 14.52 | BG10: =BG9+BF10 -> #REF! | BH10: =IF(AT10="UDARA","U","N")&LEFT($C$4,2)&MID($C$4,4,2)&LEFT(A10,3)&MID(E10,2,2)&VLOOKUP(E10,Acuan_Reference!C:L,10,0) -> N1501BLP71ED | BI10: SUHU NORMAL | BJ10: FAR2 | BK10: CM3 | BL10: G
A11: BTM1 | B11: SUHADI | C11: ULTRA SAKTI | D11: 4P719 | E11: P7100002 | F11: INDAL - CTN @10 TAB AMPLOP | G11: FAST MOVING | H11: DROPPING | I11: 16500 | J11: 216 | K11: 492 | L11: 173 | M11: 526 | N11: 543 | O11: 791 | P11: 488 | Q11: 359 | R11: 528 | S11: 869 | T11: 481 | U11: 599 | V11: 649.66667 | W11: =AVERAGE(T11,U11,AL11) -> 599.33333 | X11: 252 | Y11: 0 | Z11: 0 | AA11: 1008 | AB11: 0 | AC11: 240 | AD11: 0 | AE11: =Z11+AA11+AC11+AD11 -> 1248 | AF11: =IFERROR(IF(V11<0,9999,AE11/V11),9999) -> 1.9209851 | AG11: =IFERROR(IF(W11<0,9999,(Z11+AA11+AC11)/W11),9999) -> 2.0823137 | AH11: 10200 | AI11: 0 | AJ11: 10200 | AK11: 651 | AL11: 718 | AM11: 1.5 | AN11: =IF(AM11*W11<0,0,AM11*W11) -> 899 | AO11: 120 | AP11: 120 | AQ11: KPST | AR11: 2 | AS11: 0.53333333 | AT11: NON UDARA | AU11: =IF(OR(H11="PINDAH DISTRIBUTOR",H11="PESTA NO BUFFER",H11="PESTA"),0,IF(AL11+AN11<AE11,0,IF((0.75*((AL11+AN11)-AE11))<0,0,0.75*((AL11+AN11)-AE11)))) -> 276.75 | AV11: =IFERROR(ROUNDUP(AU11/AO11,0)*AO11,9999) -> 360 | AW11: =IFERROR(IF(W11<0,9999,((ROUNDUP(AU11/AO11,0)*AO11)+AE11)/W11),9999) -> 2.6829811 | AX11: =IFERROR(IF(W11<0,9999,((ROUNDUP(AU11/AP11,0)*AP11)+AE11-AL11)/W11),9999) -> 1.4849833 | AY11: =IF(H11="DROPPING",IF(AND(AW11>3,AX11>3),0,IF(AND(AW11<=3,AX11<=3),ROUNDUP(AU11/AO11,0)*AO11,ROUNDUP(AU11/AP11,0)*AP11)),0) -> 360 | AZ11: =IF(AH11<=0,0,IF(H11="DROPPING",IF(AND(AW11>3,AX11>3),0,IF(AND(AW11<=3,AX11<=3),ROUNDUP(AU11/AO11,0)*AO11,ROUNDUP(AU11/AP11,0)*AP11)),0)) -> 360 | BA11: =IF(AND(AW11>3,AX11>3),"Kelipatan Kirim/Master box > 3x FC+index",IF(AF11<=AS11,"1",IF(AND(AF11>AS11,AF11<=AM11),"2","3"))) -> 3 | BB11: 0.00076752 | BC11: =BB11*AZ11 -> 0.2763072 | BD11: =BD10+BC11 -> #REF! | BE11: 0.121 | BF11: =BE11*AY11 -> 43.56 | BG11: =BG10+BF11 -> #REF! | BH11: =IF(AT11="UDARA","U","N")&LEFT($C$4,2)&MID($C$4,4,2)&LEFT(A11,3)&MID(E11,2,2)&VLOOKUP(E11,Acuan_Reference!C:L,10,0) -> N1501BTM71ED | BI11: SUHU NORMAL | BJ11: FAR2 | BK11: CM3 | BL11: G
A12: CRB1 | B12: SUHADI | C12: ULTRA SAKTI | D12: 4P719 | E12: P7100002 | F12: INDAL - CTN @10 TAB AMPLOP | G12: FAST MOVING | H12: DROPPING | I12: 16500 | J12: 116 | K12: 792 | L12: 881 | M12: 962 | N12: 1501 | O12: 378 | P12: 1729 | Q12: 257 | R12: 868 | S12: 1505 | T12: 273 | U12: 1495 | V12: 1091 | W12: =AVERAGE(T12,U12,AL12) -> 926.66667 | X12: 174 | Y12: 0 | Z12: 0 | AA12: 306 | AB12: 0 | AC12: 720 | AD12: 0 | AE12: =Z12+AA12+AC12+AD12 -> 1026 | AF12: =IFERROR(IF(V12<0,9999,AE12/V12),9999) -> 0.94042163 | AG12: =IFERROR(IF(W12<0,9999,(Z12+AA12+AC12)/W12),9999) -> 1.1071942 | AH12: 10200 | AI12: 0 | AJ12: 10200 | AK12: 974 | AL12: 1012 | AM12: 0.8 | AN12: =IF(AM12*W12<0,0,AM12*W12) -> 741.33333 | AO12: 120 | AP12: 120 | AQ12: KPST | AR12: 4 | AS12: 0.066666667 | AT12: NON UDARA | AU12: =IF(OR(H12="PINDAH DISTRIBUTOR",H12="PESTA NO BUFFER",H12="PESTA"),0,IF(AL12+AN12<AE12,0,IF((0.75*((AL12+AN12)-AE12))<0,0,0.75*((AL12+AN12)-AE12)))) -> 545.5 | AV12: =IFERROR(ROUNDUP(AU12/AO12,0)*AO12,9999) -> 600 | AW12: =IFERROR(IF(W12<0,9999,((ROUNDUP(AU12/AO12,0)*AO12)+AE12)/W12),9999) -> 1.7546763 | AX12: =IFERROR(IF(W12<0,9999,((ROUNDUP(AU12/AP12,0)*AP12)+AE12-AL12)/W12),9999) -> 0.66258993 | AY12: =IF(H12="DROPPING",IF(AND(AW12>3,AX12>3),0,IF(AND(AW12<=3,AX12<=3),ROUNDUP(AU12/AO12,0)*AO12,ROUNDUP(AU12/AP12,0)*AP12)),0) -> 600 | AZ12: =IF(AH12<=0,0,IF(H12="DROPPING",IF(AND(AW12>3,AX12>3),0,IF(AND(AW12<=3,AX12<=3),ROUNDUP(AU12/AO12,0)*AO12,ROUNDUP(AU12/AP12,0)*AP12)),0)) -> 600 | BA12: =IF(AND(AW12>3,AX12>3),"Kelipatan Kirim/Master box > 3x FC+index",IF(AF12<=AS12,"1",IF(AND(AF12>AS12,AF12<=AM12),"2","3"))) -> 3 | BB12: 0.00076752 | BC12: =BB12*AZ12 -> 0.460512 | BD12: =BD11+BC12 -> #REF! | BE12: 0.121 | BF12: =BE12*AY12 -> 72.6 | BG12: =BG11+BF12 -> #REF! | BH12: =IF(AT12="UDARA","U","N")&LEFT($C$4,2)&MID($C$4,4,2)&LEFT(A12,3)&MID(E12,2,2)&VLOOKUP(E12,Acuan_Reference!C:L,10,0) -> N1501CRB71ED | BI12: SUHU NORMAL | BJ12: FAR2 | BK12: CM3 | BL12: G
A13: DPS1 | B13: SUHADI | C13: ULTRA SAKTI | D13: 4P719 | E13: P7100002 | F13: INDAL - CTN @10 TAB AMPLOP | G13: FAST MOVING | H13: DROPPING | I13: 16500 | J13: 438 | K13: 801 | L13: 777 | M13: 790 | N13: 755 | O13: 717 | P13: 781 | Q13: 784 | R13: 762 | S13: 1276 | T13: 940 | U13: 998 | V13: 1071.3333 | W13: =AVERAGE(T13,U13,AL13) -> 1025.3333 | X13: 449 | Y13: 0 | Z13: 0 | AA13: 1027 | AB13: 0 | AC13: 480 | AD13: 0 | AE13: =Z13+AA13+AC13+AD13 -> 1507 | AF13: =IFERROR(IF(V13<0,9999,AE13/V13),9999) -> 1.4066584 | AG13: =IFERROR(IF(W13<0,9999,(Z13+AA13+AC13)/W13),9999) -> 1.4697659 | AH13: 10200 | AI13: 0 | AJ13: 10200 | AK13: 1046 | AL13: 1138 | AM13: 0.8 | AN13: =IF(AM13*W13<0,0,AM13*W13) -> 820.26667 | AO13: 120 | AP13: 120 | AQ13: KPST | AR13: 8 | AS13: 0.13333333 | AT13: NON UDARA | AU13: =IF(OR(H13="PINDAH DISTRIBUTOR",H13="PESTA NO BUFFER",H13="PESTA"),0,IF(AL13+AN13<AE13,0,IF((0.75*((AL13+AN13)-AE13))<0,0,0.75*((AL13+AN13)-AE13)))) -> 338.45 | AV13: =IFERROR(ROUNDUP(AU13/AO13,0)*AO13,9999) -> 360 | AW13: =IFERROR(IF(W13<0,9999,((ROUNDUP(AU13/AO13,0)*AO13)+AE13)/W13),9999) -> 1.8208713 | AX13: =IFERROR(IF(W13<0,9999,((ROUNDUP(AU13/AP13,0)*AP13)+AE13-AL13)/W13),9999) -> 0.7109883 | AY13: =IF(H13="DROPPING",IF(AND(AW13>3,AX13>3),0,IF(AND(AW13<=3,AX13<=3),ROUNDUP(AU13/AO13,0)*AO13,ROUNDUP(AU13/AP13,0)*AP13)),0) -> 360 | AZ13: =IF(AH13<=0,0,IF(H13="DROPPING",IF(AND(AW13>3,AX13>3),0,IF(AND(AW13<=3,AX13<=3),ROUNDUP(AU13/AO13,0)*AO13,ROUNDUP(AU13/AP13,0)*AP13)),0)) -> 360 | BA13: =IF(AND(AW13>3,AX13>3),"Kelipatan Kirim/Master box > 3x FC+index",IF(AF13<=AS13,"1",IF(AND(AF13>AS13,AF13<=AM13),"2","3"))) -> 3 | BB13: 0.00076752 | BC13: =BB13*AZ13 -> 0.2763072 | BD13: =BD12+BC13 -> #REF! | BE13: 0.121 | BF13: =BE13*AY13 -> 43.56 | BG13: =BG12+BF13 -> #REF! | BH13: =IF(AT13="UDARA","U","N")&LEFT($C$4,2)&MID($C$4,4,2)&LEFT(A13,3)&MID(E13,2,2)&VLOOKUP(E13,Acuan_Reference!C:L,10,0) -> N1501DPS71ED | BI13: SUHU NORMAL | BJ13: FAR2 | BK13: CM3 | BL13: G
A14: JAK1 | B14: SUHADI | C14: ULTRA SAKTI | D14: 4P719 | E14: P7100002 | F14: INDAL - CTN @10 TAB AMPLOP | G14: FAST MOVING | H14: DROPPING | I14: 16500 | J14: 280 | K14: 541 | L14: 451 | M14: 1729 | N14: 3268 | O14: 889 | P14: 2205 | Q14: 2693 | R14: 1793 | S14: 2259 | T14: 1412 | U14: 5298 | V14: 2989.6667 | W14: =AVERAGE(T14,U14,AL14) -> 2932.6667 | X14: 614 | Y14: 0 | Z14: 0 | AA14: 1705 | AB14: 0 | AC14: 0 | AD14: 0 | AE14: =Z14+AA14+AC14+AD14 -> 1705 | AF14: =IFERROR(IF(V14<0,9999,AE14/V14),9999) -> 0.57029769 | AG14: =IFERROR(IF(W14<0,9999,(Z14+AA14+AC14)/W14),9999) -> 0.58138213 | AH14: 10200 | AI14: 0 | AJ14: 10200 | AK14: 2496 | AL14: 2088 | AM14: 0.25 | AN14: =IF(AM14*W14<0,0,AM14*W14) -> 733.16667 | AO14: 120 | AP14: 120 | AQ14: KPST | AR14: 12 | AS14: 0.033333333 | AT14: NON UDARA | AU14: =IF(OR(H14="PINDAH DISTRIBUTOR",H14="PESTA NO BUFFER",H14="PESTA"),0,IF(AL14+AN14<AE14,0,IF((0.75*((AL14+AN14)-AE14))<0,0,0.75*((AL14+AN14)-AE14)))) -> 837.125 | AV14: =IFERROR(ROUNDUP(AU14/AO14,0)*AO14,9999) -> 840 | AW14: =IFERROR(IF(W14<0,9999,((ROUNDUP(AU14/AO14,0)*AO14)+AE14)/W14),9999) -> 0.86781087 | AX14: =IFERROR(IF(W14<0,9999,((ROUNDUP(AU14/AP14,0)*AP14)+AE14-AL14)/W14),9999) -> 0.15583087 | AY14: =IF(H14="DROPPING",IF(AND(AW14>3,AX14>3),0,IF(AND(AW14<=3,AX14<=3),ROUNDUP(AU14/AO14,0)*AO14,ROUNDUP(AU14/AP14,0)*AP14)),0) -> 840 | AZ14: =IF(AH14<=0,0,IF(H14="DROPPING",IF(AND(AW14>3,AX14>3),0,IF(AND(AW14<=3,AX14<=3),ROUNDUP(AU14/AO14,0)*AO14,ROUNDUP(AU14/AP14,0)*AP14)),0)) -> 840 | BA14: =IF(AND(AW14>3,AX14>3),"Kelipatan Kirim/Master box > 3x FC+index",IF(AF14<=AS14,"1",IF(AND(AF14>AS14,AF14<=AM14),"2","3"))) -> 3 | BB14: 0.00076752 | BC14: =BB14*AZ14 -> 0.6447168 | BD14: =BD13+BC14 -> #REF! | BE14: 0.121 | BF14: =BE14*AY14 -> 101.64 | BG14: =BG13+BF14 -> #REF! | BH14: =IF(AT14="UDARA","U","N")&LEFT($C$4,2)&MID($C$4,4,2)&LEFT(A14,3)&MID(E14,2,2)&VLOOKUP(E14,Acuan_Reference!C:L,10,0) -> N1501JAK71ED | BI14: SUHU NORMAL | BJ14: FAR2 | BK14: CM3 | BL14: G
A15: JBI1 | B15: SUHADI | C15: ULTRA SAKTI | D15: 4P719 | E15: P7100002 | F15: INDAL - CTN @10 TAB AMPLOP | G15: FAST MOVING | H15: DROPPING | I15: 16500 | J15: 176 | K15: 100 | L15: 179 | M15: 338 | N15: 146 | O15: 183 | P15: 136 | Q15: 196 | R15: 324 | S15: 168 | T15: 96 | U15: 226 | V15: 163.33333 | W15: =AVERAGE(T15,U15,AL15) -> 182.33333 | X15: 46 | Y15: 0 | Z15: 0 | AA15: 450 | AB15: 0 | AC15: 0 | AD15: 0 | AE15: =Z15+AA15+AC15+AD15 -> 450 | AF15: =IFERROR(IF(V15<0,9999,AE15/V15),9999) -> 2.755102 | AG15: =IFERROR(IF(W15<0,9999,(Z15+AA15+AC15)/W15),9999) -> 2.4680073 | AH15: 10200 | AI15: 0 | AJ15: 10200 | AK15: 256 | AL15: 225 | AM15: 1.2 | AN15: =IF(AM15*W15<0,0,AM15*W15) -> 218.8 | AO15: 120 | AP15: 120 | AQ15: KPST | AR15: 2 | AS15: 0.2 | AT15: NON UDARA | AU15: =IF(OR(H15="PINDAH DISTRIBUTOR",H15="PESTA NO BUFFER",H15="PESTA"),0,IF(AL15+AN15<AE15,0,IF((0.75*((AL15+AN15)-AE15))<0,0,0.75*((AL15+AN15)-AE15)))) -> 0 | AV15: =IFERROR(ROUNDUP(AU15/AO15,0)*AO15,9999) -> 0 | AW15: =IFERROR(IF(W15<0,9999,((ROUNDUP(AU15/AO15,0)*AO15)+AE15)/W15),9999) -> 2.4680073 | AX15: =IFERROR(IF(W15<0,9999,((ROUNDUP(AU15/AP15,0)*AP15)+AE15-AL15)/W15),9999) -> 1.2340037 | AY15: =IF(H15="DROPPING",IF(AND(AW15>3,AX15>3),0,IF(AND(AW15<=3,AX15<=3),ROUNDUP(AU15/AO15,0)*AO15,ROUNDUP(AU15/AP15,0)*AP15)),0) -> 0 | AZ15: =IF(AH15<=0,0,IF(H15="DROPPING",IF(AND(AW15>3,AX15>3),0,IF(AND(AW15<=3,AX15<=3),ROUNDUP(AU15/AO15,0)*AO15,ROUNDUP(AU15/AP15,0)*AP15)),0)) -> 0 | BA15: =IF(AND(AW15>3,AX15>3),"Kelipatan Kirim/Master box > 3x FC+index",IF(AF15<=AS15,"1",IF(AND(AF15>AS15,AF15<=AM15),"2","3"))) -> 3 | BB15: 0.00076752 | BC15: =BB15*AZ15 -> 0 | BD15: =BD14+BC15 -> #REF! | BE15: 0.121 | BF15: =BE15*AY15 -> 0 | BG15: =BG14+BF15 -> #REF! | BH15: =IF(AT15="UDARA","U","N")&LEFT($C$4,2)&MID($C$4,4,2)&LEFT(A15,3)&MID(E15,2,2)&VLOOKUP(E15,Acuan_Reference!C:L,10,0) -> N1501JBI71ED | BI15: SUHU NORMAL | BJ15: FAR2 | BK15: CM3 | BL15: G
A16: JKT3 | B16: SUHADI | C16: ULTRA SAKTI | D16: 4P719 | E16: P7100002 | F16: INDAL - CTN @10 TAB AMPLOP | G16: FAST MOVING | H16: DROPPING | I16: 16500 | J16: 4198 | K16: 1823 | L16: 3503 | M16: 3014 | N16: 3096 | O16: 1648 | P16: 3039 | Q16: 2893 | R16: 3046 | S16: 3039 | T16: 2984 | U16: 3307 | V16: 3110 | W16: =AVERAGE(T16,U16,AL16) -> 3252.3333 | X16: 184 | Y16: 0 | Z16: 0 | AA16: 3127 | AB16: 0 | AC16: 1080 | AD16: 0 | AE16: =Z16+AA16+AC16+AD16 -> 4207 | AF16: =IFERROR(IF(V16<0,9999,AE16/V16),9999) -> 1.3527331 | AG16: =IFERROR(IF(W16<0,9999,(Z16+AA16+AC16)/W16),9999) -> 1.2935328 | AH16: 10200 | AI16: 0 | AJ16: 10200 | AK16: 3323 | AL16: 3466 | AM16: 0.5 | AN16: =IF(AM16*W16<0,0,AM16*W16) -> 1626.1667 | AO16: 120 | AP16: 120 | AQ16: KPST | AR16: 20 | AS16: 0.033333333 | AT16: NON UDARA | AU16: =IF(OR(H16="PINDAH DISTRIBUTOR",H16="PESTA NO BUFFER",H16="PESTA"),0,IF(AL16+AN16<AE16,0,IF((0.75*((AL16+AN16)-AE16))<0,0,0.75*((AL16+AN16)-AE16)))) -> 663.875 | AV16: =IFERROR(ROUNDUP(AU16/AO16,0)*AO16,9999) -> 720 | AW16: =IFERROR(IF(W16<0,9999,((ROUNDUP(AU16/AO16,0)*AO16)+AE16)/W16),9999) -> 1.5149124 | AX16: =IFERROR(IF(W16<0,9999,((ROUNDUP(AU16/AP16,0)*AP16)+AE16-AL16)/W16),9999) -> 0.44921595 | AY16: =IF(H16="DROPPING",IF(AND(AW16>3,AX16>3),0,IF(AND(AW16<=3,AX16<=3),ROUNDUP(AU16/AO16,0)*AO16,ROUNDUP(AU16/AP16,0)*AP16)),0) -> 720 | AZ16: =IF(AH16<=0,0,IF(H16="DROPPING",IF(AND(AW16>3,AX16>3),0,IF(AND(AW16<=3,AX16<=3),ROUNDUP(AU16/AO16,0)*AO16,ROUNDUP(AU16/AP16,0)*AP16)),0)) -> 720 | BA16: =IF(AND(AW16>3,AX16>3),"Kelipatan Kirim/Master box > 3x FC+index",IF(AF16<=AS16,"1",IF(AND(AF16>AS16,AF16<=AM16),"2","3"))) -> 3 | BB16: 0.00076752 | BC16: =BB16*AZ16 -> 0.5526144 | BD16: =BD15+BC16 -> #REF! | BE16: 0.121 | BF16: =BE16*AY16 -> 87.12 | BG16: =BG15+BF16 -> #REF! | BH16: =IF(AT16="UDARA","U","N")&LEFT($C$4,2)&MID($C$4,4,2)&LEFT(A16,3)&MID(E16,2,2)&VLOOKUP(E16,Acuan_Reference!C:L,10,0) -> N1501JKT71ED | BI16: SUHU NORMAL | BJ16: FAR2 | BK16: CM3 | BL16: G
A17: JMR1 | B17: SUHADI | C17: ULTRA SAKTI | D17: 4P719 | E17: P7100002 | F17: INDAL - CTN @10 TAB AMPLOP | G17: FAST MOVING | H17: DROPPING | I17: 16500 | J17: 812 | K17: 715 | L17: 1093 | M17: 1022 | N17: 593 | O17: 1075 | P17: 495 | Q17: 696 | R17: 827 | S17: 918 | T17: 753 | U17: 610 | V17: 760.33333 | W17: =AVERAGE(T17,U17,AL17) -> 772.66667 | X17: 184 | Y17: 0 | Z17: 0 | AA17: 1033 | AB17: 0 | AC17: 0 | AD17: 480 | AE17: =Z17+AA17+AC17+AD17 -> 1513 | AF17: =IFERROR(IF(V17<0,9999,AE17/V17),9999) -> 1.9899167 | AG17: =IFERROR(IF(W17<0,9999,(Z17+AA17+AC17)/W17),9999) -> 1.3369284 | AH17: 10200 | AI17: 0 | AJ17: 10200 | AK17: 904 | AL17: 955 | AM17: 0.9 | AN17: =IF(AM17*W17<0,0,AM17*W17) -> 695.4 | AO17: 120 | AP17: 120 | AQ17: KPST | AR17: 4 | AS17: 0.1 | AT17: NON UDARA | AU17: =IF(OR(H17="PINDAH DISTRIBUTOR",H17="PESTA NO BUFFER",H17="PESTA"),0,IF(AL17+AN17<AE17,0,IF((0.75*((AL17+AN17)-AE17))<0,0,0.75*((AL17+AN17)-AE17)))) -> 103.05 | AV17: =IFERROR(ROUNDUP(AU17/AO17,0)*AO17,9999) -> 120 | AW17: =IFERROR(IF(W17<0,9999,((ROUNDUP(AU17/AO17,0)*AO17)+AE17)/W17),9999) -> 2.1134599 | AX17: =IFERROR(IF(W17<0,9999,((ROUNDUP(AU17/AP17,0)*AP17)+AE17-AL17)/W17),9999) -> 0.87748059 | AY17: =IF(H17="DROPPING",IF(AND(AW17>3,AX17>3),0,IF(AND(AW17<=3,AX17<=3),ROUNDUP(AU17/AO17,0)*AO17,ROUNDUP(AU17/AP17,0)*AP17)),0) -> 120 | AZ17: =IF(AH17<=0,0,IF(H17="DROPPING",IF(AND(AW17>3,AX17>3),0,IF(AND(AW17<=3,AX17<=3),ROUNDUP(AU17/AO17,0)*AO17,ROUNDUP(AU17/AP17,0)*AP17)),0)) -> 120 | BA17: =IF(AND(AW17>3,AX17>3),"Kelipatan Kirim/Master box > 3x FC+index",IF(AF17<=AS17,"1",IF(AND(AF17>AS17,AF17<=AM17),"2","3"))) -> 3 | BB17: 0.00076752 | BC17: =BB17*AZ17 -> 0.0921024 | BD17: =BD16+BC17 -> #REF! | BE17: 0.121 | BF17: =BE17*AY17 -> 14.52 | BG17: =BG16+BF17 -> #REF! | BH17: =IF(AT17="UDARA","U","N")&LEFT($C$4,2)&MID($C$4,4,2)&LEFT(A17,3)&MID(E17,2,2)&VLOOKUP(E17,Acuan_Reference!C:L,10,0) -> N1501JMR71ED | BI17: SUHU NORMAL | BJ17: FAR2 | BK17: CM3 | BL17: G
A18: MDN1 | B18: SUHADI | C18: ULTRA SAKTI | D18: 4P719 | E18: P7100002 | F18: INDAL - CTN @10 TAB AMPLOP | G18: FAST MOVING | H18: DROPPING | I18: 16500 | J18: 191 | K18: 119 | L18: 245 | M18: 365 | N18: 292 | O18: 188 | P18: 239 | Q18: 145 | R18: 225 | S18: 312 | T18: 125 | U18: 428 | V18: 288.33333 | W18: =AVERAGE(T18,U18,AL18) -> 268.66667 | X18: 46 | Y18: 0 | Z18: 0 | AA18: 202 | AB18: 0 | AC18: 240 | AD18: 120 | AE18: =Z18+AA18+AC18+AD18 -> 562 | AF18: =IFERROR(IF(V18<0,9999,AE18/V18),9999) -> 1.9491329 | AG18: =IFERROR(IF(W18<0,9999,(Z18+AA18+AC18)/W18),9999) -> 1.6451613 | AH18: 10200 | AI18: 0 | AJ18: 10200 | AK18: 253 | AL18: 253 | AM18: 1.1 | AN18: =IF(AM18*W18<0,0,AM18*W18) -> 295.53333 | AO18: 120 | AP18: 120 | AQ18: KPST | AR18: 4 | AS18: 0.33333333 | AT18: NON UDARA | AU18: =IF(OR(H18="PINDAH DISTRIBUTOR",H18="PESTA NO BUFFER",H18="PESTA"),0,IF(AL18+AN18<AE18,0,IF((0.75*((AL18+AN18)-AE18))<0,0,0.75*((AL18+AN18)-AE18)))) -> 0 | AV18: =IFERROR(ROUNDUP(AU18/AO18,0)*AO18,9999) -> 0 | AW18: =IFERROR(IF(W18<0,9999,((ROUNDUP(AU18/AO18,0)*AO18)+AE18)/W18),9999) -> 2.0918114 | AX18: =IFERROR(IF(W18<0,9999,((ROUNDUP(AU18/AP18,0)*AP18)+AE18-AL18)/W18),9999) -> 1.1501241 | AY18: =IF(H18="DROPPING",IF(AND(AW18>3,AX18>3),0,IF(AND(AW18<=3,AX18<=3),ROUNDUP(AU18/AO18,0)*AO18,ROUNDUP(AU18/AP18,0)*AP18)),0) -> 0 | AZ18: =IF(AH18<=0,0,IF(H18="DROPPING",IF(AND(AW18>3,AX18>3),0,IF(AND(AW18<=3,AX18<=3),ROUNDUP(AU18/AO18,0)*AO18,ROUNDUP(AU18/AP18,0)*AP18)),0)) -> 0 | BA18: =IF(AND(AW18>3,AX18>3),"Kelipatan Kirim/Master box > 3x FC+index",IF(AF18<=AS18,"1",IF(AND(AF18>AS18,AF18<=AM18),"2","3"))) -> 3 | BB18: 0.00076752 | BC18: =BB18*AZ18 -> 0 | BD18: =BD17+BC18 -> #REF! | BE18: 0.121 | BF18: =BE18*AY18 -> 0 | BG18: =BG17+BF18 -> #REF! | BH18: =IF(AT18="UDARA","U","N")&LEFT($C$4,2)&MID($C$4,4,2)&LEFT(A18,3)&MID(E18,2,2)&VLOOKUP(E18,Acuan_Reference!C:L,10,0) -> N1501MDN71ED | BI18: SUHU NORMAL | BJ18: FAR2 | BK18: CM3 | BL18: G
... A2917: YGY1 | B2917: SUHADI | C2917: ULTRA SAKTI | D2917: 4P717 | E2917: P71WMUS5 | F2917: WELMOVE ULTRA @5 CAP AMPLOP | G2917: FOCUS | H2917: DROPPING | I2917: 14025 | J2917: 217 | K2917: 571 | L2917: 756 | M2917: 1586 | N2917: 870 | O2917: 658 | P2917: 363 | Q2917: 416 | R2917: 1154 | S2917: 1303 | T2917: 546 | U2917: 1267 | V2917: 1038.6667 | W2917: =AVERAGE(T2917,U2917,AL2917) -> 830.33333 | X2917: 93 | Y2917: 0 | Z2917: 0 | AA2917: 1136 | AB2917: 0 | AC2917: 0 | AD2917: 0 | AE2917: =Z2917+AA2917+AC2917+AD2917 -> 1136 | AF2917: =IFERROR(IF(V2917<0,9999,AE2917/V2917),9999) -> 1.0937099 | AG2917: =IFERROR(IF(W2917<0,9999,(Z2917+AA2917+AC2917)/W2917),9999) -> 1.3681253 | AH2917: 2736 | AI2917: 0 | AJ2917: 1008 | AK2917: 1118 | AL2917: 678 | AM2917: 0.7 | AN2917: =IF(AM2917*W2917<0,0,AM2917*W2917) -> 581.23333 | AO2917: 144 | AP2917: 144 | AQ2917: KPST | AR2917: 8 | AS2917: 0.066666667 | AT2917: NON UDARA | AU2917: =IF(OR(H2917="PINDAH DISTRIBUTOR",H2917="PESTA NO BUFFER",H2917="PESTA"),0,IF(AL2917+AN2917<AE2917,0,IF((0.75*((AL2917+AN2917)-AE2917))<0,0,0.75*((AL2917+AN2917)-AE2917)))) -> 92.425 | AV2917: =IFERROR(ROUNDUP(AU2917/AO2917,0)*AO2917,9999) -> 144 | AW2917: =IFERROR(IF(W2917<0,9999,((ROUNDUP(AU2917/AO2917,0)*AO2917)+AE2917)/W2917),9999) -> 1.5415496 | AX2917: =IFERROR(IF(W2917<0,9999,((ROUNDUP(AU2917/AP2917,0)*AP2917)+AE2917-AL2917)/W2917),9999) -> 0.72501004 | AY2917: =IF(H2917="DROPPING",IF(AND(AW2917>3,AX2917>3),0,IF(AND(AW2917<=3,AX2917<=3),ROUNDUP(AU2917/AO2917,0)*AO2917,ROUNDUP(AU2917/AP2917,0)*AP2917)),0) -> 144 | AZ2917: =IF(AH2917<=0,0,IF(H2917="DROPPING",IF(AND(AW2917>3,AX2917>3),0,IF(AND(AW2917<=3,AX2917<=3),ROUNDUP(AU2917/AO2917,0)*AO2917,ROUNDUP(AU2917/AP2917,0)*AP2917)),0)) -> 144 | BA2917: =IF(AND(AW2917>3,AX2917>3),"Kelipatan Kirim/Master box > 3x FC+index",IF(AF2917<=AS2917,"1",IF(AND(AF2917>AS2917,AF2917<=AM2917),"2","3"))) -> 3 | BB2917: 7.35e-05 | BC2917: =BB2917*AZ2917 -> 0.010584 | BD2917: =BD2916+BC2917 -> #REF! | BE2917: 0.02 | BF2917: =BE2917*AY2917 -> 2.88 | BG2917: =BG2916+BF2917 -> #REF! | BH2917: =IF(AT2917="UDARA","U","N")&LEFT($C$4,2)&MID($C$4,4,2)&LEFT(A2917,3)&MID(E2917,2,2)&VLOOKUP(E2917,Acuan_Reference!C:L,10,0) -> N1501YGY71A2 | BI2917: SUHU NORMAL | BJ2917: CPO1 | BK2917: CM3 | BL2917: G

Sheet Acuan_Reference
A2: Zonasi Gudang
A4: Kode Sup | B4: Nama Sup | C4: Part No | D4: Part Description | E4: Lokasi BRG | F4: Produk Icepack | G4: Category Product | H4: zona | I4: Rak | J4: PIC | K4: Nama | L4: Inisial | M4: Sediaan | N4: USER HP PENATA
A5: P12 | C5: P1226340 | D5: BIB6B SILICON BIB BLUE | E5: RWB1 | H5: B16 | J5: ZA | K5: ZAKARIA | L5: A1 | N5: KPST-PNTGUD36
A6: P12 | C6: P1226342 | D6: BIB6G SILICONE BIB GREEN | E6: RWB1 | H6: B16 | J6: ZA | K6: ZAKARIA | L6: A1 | N6: KPST-PNTGUD36
A7: P12 | C7: P1226341 | D7: BIB6P SILICONE BIB PINK | E7: RWB1 | H7: B16 | J7: ZA | K7: ZAKARIA | L7: A1 | N7: KPST-PNTGUD36
A8: P12 | C8: P12DL114 | D8: BRUSH & COMB DL 1014 | E8: RWB1 | H8: B16 | J8: ZA | K8: ZAKARIA | L8: A1 | M8: P12E | N8: KPST-PNTGUD36
A9: P12 | C9: P1226277 | D9: BS370 BOTTLE BRUSH | E9: RWB1 | H9: B16 | J9: ZA | K9: ZAKARIA | L9: A1 | N9: KPST-PNTGUD36
A10: P12 | C10: P1226289 | D10: BS371 SILICONE BRUSH | E10: RWB1 | H10: B16 | J10: ZA | K10: ZAKARIA | L10: A1 | N10: KPST-PNTGUD36
A11: P12 | C11: P12BS369 | D11: COMPLETE SET BRUSH | E11: RWB1 | H11: B16 | J11: ZA | K11: ZAKARIA | L11: A1 | M11: P12E | N11: KPST-PNTGUD36
A12: P12 | C12: P12BIB02 | D12: CRUMB CATCHER BIB | E12: RWB1 | H12: B16 | J12: ZA | K12: ZAKARIA | L12: A1 | M12: P12A | N12: KPST-PNTGUD36
A13: P12 | C13: P12SK019 | D13: CUP WITH STRAW (270ML) | E13: RWB1 | H13: B16 | J13: ZA | K13: ZAKARIA | L13: A1 | N13: KPST-PNTGUD36
A14: P12 | C14: P1226276 | D14: FS609 TABLEWARE SET | E14: RWB1 | H14: B16 | J14: ZA | K14: ZAKARIA | L14: A1 | N14: KPST-PNTGUD36
A15: P12 | C15: P12BIB05 | D15: LONG BIB | E15: RWB1 | H15: B16 | J15: ZA | K15: ZAKARIA | L15: A1 | M15: P12A | N15: KPST-PNTGUD36
A16: P12 | C16: P1226272 | D16: NAS04 PICKER EAR WITH LIGHT | E16: RWB1 | H16: B16 | J16: ZA | K16: ZAKARIA | L16: A1 | N16: KPST-PNTGUD36
A17: P12 | C17: P12BIB04 | D17: SILICONE BIB | E17: RWB1 | H17: B16 | J17: ZA | K17: ZAKARIA | L17: A1 | M17: P12A | N17: KPST-PNTGUD36
A18: P12 | C18: P12FS405 | D18: SIPPER CUP WITH WEIGHTED STRAW | E18: RWB1 | H18: B16 | J18: ZA | K18: ZAKARIA | L18: A1 | M18: P12B | N18: KPST-PNTGUD36
A19: P12 | C19: P12DOTXL | D19: Dot regular XL | E19: RWB1 | H19: B16 | J19: ZA | K19: ZAKARIA | L19: A2 | M19: P12E | N19: KPST-PNTGUD36
A20: P12 | C20: P12DOT0L | D20: DOT SLIM L | E20: RWB1 | H20: B16 | J20: ZA | K20: ZAKARIA | L20: A2 | M20: P12E | N20: KPST-PNTGUD36
A21: P12 | C21: P12DOT0M | D21: DOT SLIM M | E21: RWB1 | H21: B16 | J21: ZA | K21: ZAKARIA | L21: A2 | M21: P12E | N21: KPST-PNTGUD36
A22: P12 | C22: P12DWN0L | D22: DOT WIDE NECK L | E22: RWB1 | H22: B16 | J22: ZA | K22: ZAKARIA | L22: A2 | M22: P12E | N22: KPST-PNTGUD36
A23: P12 | C23: P12DWN0M | D23: DOT WIDE NECK M | E23: RWB1 | H23: B16 | J23: ZA | K23: ZAKARIA | L23: A2 | M23: P12E | N23: KPST-PNTGUD36
A24: P12 | C24: P12DWNXL | D24: Dot wide neck XL | E24: RWB1 | H24: B16 | J24: ZA | K24: ZAKARIA | L24: A2 | M24: P12E | N24: KPST-PNTGUD36
A25: P12 | C25: P1200006 | D25: DOT0S DOT REGULAR S (SMALL) | E25: RWB1 | H25: B16 | J25: ZA | K25: ZAKARIA | L25: A2 | N25: KPST-PNTGUD36
A26: P12 | C26: P1200005 | D26: DWN0S DOT WIDE NECK S (SMALL) | E26: RWB1 | H26: B16 | J26: ZA | K26: ZAKARIA | L26: A2 | N26: KPST-PNTGUD36
A27: P12 | C27: P12FS500 | D27: FEEDING MEAL TIME | E27: RWB1 | H27: B16 | J27: ZA | K27: ZAKARIA | L27: A3 | M27: P12B | N27: KPST-PNTGUD36
A28: P12 | C28: P12FS603 | D28: FEEDING SET 5 PCS | E28: RWB1 | H28: B16 | J28: ZA | K28: ZAKARIA | L28: A3 | M28: P12B | N28: KPST-PNTGUD36
A29: P12 | C29: P12FS602 | D29: FEEDING SET 6 PCS | E29: RWB1 | H29: B16 | J29: ZA | K29: ZAKARIA | L29: A3 | M29: P12B | N29: KPST-PNTGUD36
A30: P12 | C30: P12FS601 | D30: FEEDING SET 7 PCS | E30: RWB1 | H30: B16 | J30: ZA | K30: ZAKARIA | L30: A3 | M30: P12B | N30: KPST-PNTGUD36
A31: P12 | C31: P1200025 | D31: FS607 DINO FEEDING SET | E31: RWB1 | H31: B16 | J31: ZA | K31: ZAKARIA | L31: A3 | N31: KPST-PNTGUD36
A32: P12 | C32: P1200026 | D32: FS608 PLANE FEEDING SET | E32: RWB1 | H32: B16 | J32: ZA | K32: ZAKARIA | L32: A3 | N32: KPST-PNTGUD36
A33: P12 | C33: P1226345 | D33: FS610 FEEDING SET | E33: RWB1 | H33: B16 | J33: ZA | K33: ZAKARIA | L33: A3 | N33: KPST-PNTGUD36
A34: P12 | C34: P1226356 | D34: FS66B FEEDING SET BLUE | E34: RWB1 | H34: B16 | J34: ZA | K34: ZAKARIA | L34: A3 | N34: KPST-PNTGUD36
A35: P12 | C35: P1226357 | D35: FS66P FEEDING SET PINK | E35: RWB1 | H35: B16 | J35: ZA | K35: ZAKARIA | L35: A3 | N35: KPST-PNTGUD36
A36: P12 | C36: P1226358 | D36: FS66W FEEDING SET WHITE | E36: RWB1 | H36: B16 | J36: ZA | K36: ZAKARIA | L36: A3 | N36: KPST-PNTGUD36
A37: P12 | C37: P1200007 | D37: FSD01 DUCK FEEDING SET | E37: RWB1 | H37: B16 | J37: ZA | K37: ZAKARIA | L37: A3 | N37: KPST-PNTGUD36
A38: P12 | C38: P12FS64B | D38: Set meal blue | E38: RWB1 | H38: B16 | J38: ZA | K38: ZAKARIA | L38: A3 | M38: P12D | N38: KPST-PNTGUD36
A39: P12 | C39: P12FS65G | D39: Set meal green | E39: RWB1 | H39: B16 | J39: ZA | K39: ZAKARIA | L39: A3 | M39: P12D | N39: KPST-PNTGUD36
A40: P12 | C40: P12FS64P | D40: Set meal pink | E40: RWB1 | H40: B16 | J40: ZA | K40: ZAKARIA | L40: A3 | M40: P12D | N40: KPST-PNTGUD36
A41: P12 | C41: P12FS403 | D41: ANIMAL SHAPE BOWL | E41: RWB1 | H41: B16 | J41: ZA | K41: ZAKARIA | L41: A4 | M41: P12A | N41: KPST-PNTGUD36
A42: P12 | C42: P12FS404 | D42: ANIMAL SHAPE PLATE | E42: RWB1 | H42: B16 | J42: ZA | K42: ZAKARIA | L42: A4 | M42: P12A | N42: KPST-PNTGUD36
...
